Workbook

Sheet streaming_subscriptions
A1: subscription_id | B1: customer_id | C1: Signup | D1: Canceled | E1: Cohort | F1: Renewal | G1: Months Renewed
A2: 500001 | B2: 100002 | C2: 45658 | D2: 45691 | E2: =TEXT(C2:C19103,"yyyy-mmmm") -> 2025-January | F2: =IF(ISBLANK(D2), "Yes", IF((MONTH(D2)>MONTH(C2)),"Yes","No")) -> Yes | G2: =IF(ISBLANK(D2), DATEDIF(C2, MAX(D:D), "m"), DATEDIF(C2,D2, "m")) -> 1
A3: 500002 | B3: 100034 | C3: 45658 | D3: 45858 | E3: =TEXT(C3:C19104,"yyyy-mmmm") -> 2025-January | F3: =IF(ISBLANK(D3), "Yes", IF((MONTH(D3)>MONTH(C3)),"Yes","No")) -> Yes | G3: =IF(ISBLANK(D3), DATEDIF(C3, MAX(D:D), "m"), DATEDIF(C3,D3, "m")) -> 6
A4: 500003 | B4: 100033 | C4: 45658 | D4: 45678 | E4: =TEXT(C4:C19105,"yyyy-mmmm") -> 2025-January | F4: =IF(ISBLANK(D4), "Yes", IF((MONTH(D4)>MONTH(C4)),"Yes","No")) -> No | G4: =IF(ISBLANK(D4), DATEDIF(C4, MAX(D:D), "m"), DATEDIF(C4,D4, "m")) -> 0
A5: 500004 | B5: 100031 | C5: 45658 | D5: 45661 | E5: =TEXT(C5:C19106,"yyyy-mmmm") -> 2025-January | F5: =IF(ISBLANK(D5), "Yes", IF((MONTH(D5)>MONTH(C5)),"Yes","No")) -> No | G5: =IF(ISBLANK(D5), DATEDIF(C5, MAX(D:D), "m"), DATEDIF(C5,D5, "m")) -> 0
A6: 500005 | B6: 100030 | C6: 45658 | D6: 45673 | E6: =TEXT(C6:C19107,"yyyy-mmmm") -> 2025-January | F6: =IF(ISBLANK(D6), "Yes", IF((MONTH(D6)>MONTH(C6)),"Yes","No")) -> No | G6: =IF(ISBLANK(D6), DATEDIF(C6, MAX(D:D), "m"), DATEDIF(C6,D6, "m")) -> 0
A7: 500006 | B7: 100029 | C7: 45658 | D7: 45668 | E7: =TEXT(C7:C19108,"yyyy-mmmm") -> 2025-January | F7: =IF(ISBLANK(D7), "Yes", IF((MONTH(D7)>MONTH(C7)),"Yes","No")) -> No | G7: =IF(ISBLANK(D7), DATEDIF(C7, MAX(D:D), "m"), DATEDIF(C7,D7, "m")) -> 0
A8: 500007 | B8: 100026 | C8: 45658 | E8: =TEXT(C8:C19109,"yyyy-mmmm") -> 2025-January | F8: =IF(ISBLANK(D8), "Yes", IF((MONTH(D8)>MONTH(C8)),"Yes","No")) -> Yes | G8: =IF(ISBLANK(D8), DATEDIF(C8, MAX(D:D), "m"), DATEDIF(C8,D8, "m")) -> 19
A9: 500008 | B9: 100025 | C9: 45658 | D9: 45716 | E9: =TEXT(C9:C19110,"yyyy-mmmm") -> 2025-January | F9: =IF(ISBLANK(D9), "Yes", IF((MONTH(D9)>MONTH(C9)),"Yes","No")) -> Yes | G9: =IF(ISBLANK(D9), DATEDIF(C9, MAX(D:D), "m"), DATEDIF(C9,D9, "m")) -> 1
A10: 500009 | B10: 100024 | C10: 45658 | D10: 45663 | E10: =TEXT(C10:C19111,"yyyy-mmmm") -> 2025-January | F10: =IF(ISBLANK(D10), "Yes", IF((MONTH(D10)>MONTH(C10)),"Yes","No")) -> No | G10: =IF(ISBLANK(D10), DATEDIF(C10, MAX(D:D), "m"), DATEDIF(C10,D10, "m")) -> 0
A11: 500010 | B11: 100022 | C11: 45658 | D11: 45662 | E11: =TEXT(C11:C19112,"yyyy-mmmm") -> 2025-January | F11: =IF(ISBLANK(D11), "Yes", IF((MONTH(D11)>MONTH(C11)),"Yes","No")) -> No | G11: =IF(ISBLANK(D11), DATEDIF(C11, MAX(D:D), "m"), DATEDIF(C11,D11, "m")) -> 0
A12: 500011 | B12: 100020 | C12: 45658 | D12: 46108 | E12: =TEXT(C12:C19113,"yyyy-mmmm") -> 2025-January | F12: =IF(ISBLANK(D12), "Yes", IF((MONTH(D12)>MONTH(C12)),"Yes","No")) -> Yes | G12: =IF(ISBLANK(D12), DATEDIF(C12, MAX(D:D), "m"), DATEDIF(C12,D12, "m")) -> 14
A13: 500012 | B13: 100027 | C13: 45658 | D13: 45833 | E13: =TEXT(C13:C19114,"yyyy-mmmm") -> 2025-January | F13: =IF(ISBLANK(D13), "Yes", IF((MONTH(D13)>MONTH(C13)),"Yes","No")) -> Yes | G13: =IF(ISBLANK(D13), DATEDIF(C13, MAX(D:D), "m"), DATEDIF(C13,D13, "m")) -> 5
A14: 500013 | B14: 100017 | C14: 45658 | D14: 45659 | E14: =TEXT(C14:C19115,"yyyy-mmmm") -> 2025-January | F14: =IF(ISBLANK(D14), "Yes", IF((MONTH(D14)>MONTH(C14)),"Yes","No")) -> No | G14: =IF(ISBLANK(D14), DATEDIF(C14, MAX(D:D), "m"), DATEDIF(C14,D14, "m")) -> 0
A15: 500014 | B15: 100016 | C15: 45658 | D15: 45668 | E15: =TEXT(C15:C19116,"yyyy-mmmm") -> 2025-January | F15: =IF(ISBLANK(D15), "Yes", IF((MONTH(D15)>MONTH(C15)),"Yes","No")) -> No | G15: =IF(ISBLANK(D15), DATEDIF(C15, MAX(D:D), "m"), DATEDIF(C15,D15, "m")) -> 0
A16: 500015 | B16: 100015 | C16: 45658 | D16: 45680 | E16: =TEXT(C16:C19117,"yyyy-mmmm") -> 2025-January | F16: =IF(ISBLANK(D16), "Yes", IF((MONTH(D16)>MONTH(C16)),"Yes","No")) -> No | G16: =IF(ISBLANK(D16), DATEDIF(C16, MAX(D:D), "m"), DATEDIF(C16,D16, "m")) -> 0
A17: 500016 | B17: 100014 | C17: 45658 | D17: 45768 | E17: =TEXT(C17:C19118,"yyyy-mmmm") -> 2025-January | F17: =IF(ISBLANK(D17), "Yes", IF((MONTH(D17)>MONTH(C17)),"Yes","No")) -> Yes | G17: =IF(ISBLANK(D17), DATEDIF(C17, MAX(D:D), "m"), DATEDIF(C17,D17, "m")) -> 3
A18: 500017 | B18: 100012 | C18: 45658 | D18: 45767 | E18: =TEXT(C18:C19119,"yyyy-mmmm") -> 2025-January | F18: =IF(ISBLANK(D18), "Yes", IF((MONTH(D18)>MONTH(C18)),"Yes","No")) -> Yes | G18: =IF(ISBLANK(D18), DATEDIF(C18, MAX(D:D), "m"), DATEDIF(C18,D18, "m")) -> 3
A19: 500018 | B19: 100010 | C19: 45658 | D19: 45723 | E19: =TEXT(C19:C19120,"yyyy-mmmm") -> 2025-January | F19: =IF(ISBLANK(D19), "Yes", IF((MONTH(D19)>MONTH(C19)),"Yes","No")) -> Yes | G19: =IF(ISBLANK(D19), DATEDIF(C19, MAX(D:D), "m"), DATEDIF(C19,D19, "m")) -> 2
A20: 500019 | B20: 100008 | C20: 45658 | D20: 45707 | E20: =TEXT(C20:C19121,"yyyy-mmmm") -> 2025-January | F20: =IF(ISBLANK(D20), "Yes", IF((MONTH(D20)>MONTH(C20)),"Yes","No")) -> Yes | G20: =IF(ISBLANK(D20), DATEDIF(C20, MAX(D:D), "m"), DATEDIF(C20,D20, "m")) -> 1
... A36: 500035 | B36: 100052 | C36: 45659 | D36: 45703 | E36: =TEXT(C36:C19137,"yyyy-mmmm") -> 2025-January | F36: =IF(ISBLANK(D36), "Yes", IF((MONTH(D36)>MONTH(C36)),"Yes","No")) -> Yes | G36: =IF(ISBLANK(D36), DATEDIF(C36, MAX(D:D), "m"), DATEDIF(C36,D36, "m")) -> 1
A37: 500036 | B37: 100035 | C37: 45659 | E37: =TEXT(C37:C19138,"yyyy-mmmm") -> 2025-January | F37: =IF(ISBLANK(D37), "Yes", IF((MONTH(D37)>MONTH(C37)),"Yes","No")) -> Yes | G37: =IF(ISBLANK(D37), DATEDIF(C37, MAX(D:D), "m"), DATEDIF(C37,D37, "m")) -> 19
A38: 500037 | B38: 100037 | C38: 45659 | E38: =TEXT(C38:C19139,"yyyy-mmmm") -> 2025-January | F38: =IF(ISBLANK(D38), "Yes", IF((MONTH(D38)>MONTH(C38)),"Yes","No")) -> Yes | G38: =IF(ISBLANK(D38), DATEDIF(C38, MAX(D:D), "m"), DATEDIF(C38,D38, "m")) -> 19
A39: 500038 | B39: 100041 | C39: 45659 | D39: 45686 | E39: =TEXT(C39:C19140,"yyyy-mmmm") -> 2025-January | F39: =IF(ISBLANK(D39), "Yes", IF((MONTH(D39)>MONTH(C39)),"Yes","No")) -> No | G39: =IF(ISBLANK(D39), DATEDIF(C39, MAX(D:D), "m"), DATEDIF(C39,D39, "m")) -> 0
A40: 500039 | B40: 100042 | C40: 45659 | D40: 45873 | E40: =TEXT(C40:C19141,"yyyy-mmmm") -> 2025-January | F40: =IF(ISBLANK(D40), "Yes", IF((MONTH(D40)>MONTH(C40)),"Yes","No")) -> Yes | G40: =IF(ISBLANK(D40), DATEDIF(C40, MAX(D:D), "m"), DATEDIF(C40,D40, "m")) -> 7
A41: 500040 | B41: 100039 | C41: 45659 | D41: 45668 | E41: =TEXT(C41:C19142,"yyyy-mmmm") -> 2025-January | F41: =IF(ISBLANK(D41), "Yes", IF((MONTH(D41)>MONTH(C41)),"Yes","No")) -> No | G41: =IF(ISBLANK(D41), DATEDIF(C41, MAX(D:D), "m"), DATEDIF(C41,D41, "m")) -> 0
A42: 500041 | B42: 100045 | C42: 45659 | E42: =TEXT(C42:C19143,"yyyy-mmmm") -> 2025-January | F42: =IF(ISBLANK(D42), "Yes", IF((MONTH(D42)>MONTH(C42)),"Yes","No")) -> Yes | G42: =IF(ISBLANK(D42), DATEDIF(C42, MAX(D:D), "m"), DATEDIF(C42,D42, "m")) -> 19
A43: 500042 | B43: 100046 | C43: 45659 | D43: 45722 | E43: =TEXT(C43:C19144,"yyyy-mmmm") -> 2025-January | F43: =IF(ISBLANK(D43), "Yes", IF((MONTH(D43)>MONTH(C43)),"Yes","No")) -> Yes | G43: =IF(ISBLANK(D43), DATEDIF(C43, MAX(D:D), "m"), DATEDIF(C43,D43, "m")) -> 2
A44: 500043 | B44: 100048 | C44: 45659 | D44: 45768 | E44: =TEXT(C44:C19145,"yyyy-mmmm") -> 2025-January | F44: =IF(ISBLANK(D44), "Yes", IF((MONTH(D44)>MONTH(C44)),"Yes","No")) -> Yes | G44: =IF(ISBLANK(D44), DATEDIF(C44, MAX(D:D), "m"), DATEDIF(C44,D44, "m")) -> 3
A45: 500044 | B45: 100050 | C45: 45659 | D45: 45686 | E45: =TEXT(C45:C19146,"yyyy-mmmm") -> 2025-January | F45: =IF(ISBLANK(D45), "Yes", IF((MONTH(D45)>MONTH(C45)),"Yes","No")) -> No | G45: =IF(ISBLANK(D45), DATEDIF(C45, MAX(D:D), "m"), DATEDIF(C45,D45, "m")) -> 0
A46: 500045 | B46: 100044 | C46: 45659 | E46: =TEXT(C46:C19147,"yyyy-mmmm") -> 2025-January | F46: =IF(ISBLANK(D46), "Yes", IF((MONTH(D46)>MONTH(C46)),"Yes","No")) -> Yes | G46: =IF(ISBLANK(D46), DATEDIF(C46, MAX(D:D), "m"), DATEDIF(C46,D46, "m")) -> 19
A47: 500046 | B47: 100081 | C47: 45660 | D47: 45685 | E47: =TEXT(C47:C19148,"yyyy-mmmm") -> 2025-January | F47: =IF(ISBLANK(D47), "Yes", IF((MONTH(D47)>MONTH(C47)),"Yes","No")) -> No | G47: =IF(ISBLANK(D47), DATEDIF(C47, MAX(D:D), "m"), DATEDIF(C47,D47, "m")) -> 0
A48: 500047 | B48: 100087 | C48: 45660 | D48: 46068 | E48: =TEXT(C48:C19149,"yyyy-mmmm") -> 2025-January | F48: =IF(ISBLANK(D48), "Yes", IF((MONTH(D48)>MONTH(C48)),"Yes","No")) -> Yes | G48: =IF(ISBLANK(D48), DATEDIF(C48, MAX(D:D), "m"), DATEDIF(C48,D48, "m")) -> 13
A49: 500048 | B49: 100085 | C49: 45660 | D49: 45677 | E49: =TEXT(C49:C19150,"yyyy-mmmm") -> 2025-January | F49: =IF(ISBLANK(D49), "Yes", IF((MONTH(D49)>MONTH(C49)),"Yes","No")) -> No | G49: =IF(ISBLANK(D49), DATEDIF(C49, MAX(D:D), "m"), DATEDIF(C49,D49, "m")) -> 0
A50: 500049 | B50: 100084 | C50: 45660 | D50: 45690 | E50: =TEXT(C50:C19151,"yyyy-mmmm") -> 2025-January | F50: =IF(ISBLANK(D50), "Yes", IF((MONTH(D50)>MONTH(C50)),"Yes","No")) -> Yes | G50: =IF(ISBLANK(D50), DATEDIF(C50, MAX(D:D), "m"), DATEDIF(C50,D50, "m")) -> 0
A51: 500050 | B51: 100082 | C51: 45660 | D51: 45835 | E51: =TEXT(C51:C19152,"yyyy-mmmm") -> 2025-January | F51: =IF(ISBLANK(D51), "Yes", IF((MONTH(D51)>MONTH(C51)),"Yes","No")) -> Yes | G51: =IF(ISBLANK(D51), DATEDIF(C51, MAX(D:D), "m"), DATEDIF(C51,D51, "m")) -> 5
A52: 500051 | B52: 100079 | C52: 45660 | D52: 45665 | E52: =TEXT(C52:C19153,"yyyy-mmmm") -> 2025-January | F52: =IF(ISBLANK(D52), "Yes", IF((MONTH(D52)>MONTH(C52)),"Yes","No")) -> No | G52: =IF(ISBLANK(D52), DATEDIF(C52, MAX(D:D), "m"), DATEDIF(C52,D52, "m")) -> 0
A53: 500052 | B53: 100078 | C53: 45660 | D53: 45708 | E53: =TEXT(C53:C19154,"yyyy-mmmm") -> 2025-January | F53: =IF(ISBLANK(D53), "Yes", IF((MONTH(D53)>MONTH(C53)),"Yes","No")) -> Yes | G53: =IF(ISBLANK(D53), DATEDIF(C53, MAX(D:D), "m"), DATEDIF(C53,D53, "m")) -> 1
A54: 500053 | B54: 100077 | C54: 45660 | D54: 45664 | E54: =TEXT(C54:C19155,"yyyy-mmmm") -> 2025-January | F54: =IF(ISBLANK(D54), "Yes", IF((MONTH(D54)>MONTH(C54)),"Yes","No")) -> No | G54: =IF(ISBLANK(D54), DATEDIF(C54, MAX(D:D), "m"), DATEDIF(C54,D54, "m")) -> 0
A55: 500054 | B55: 100075 | C55: 45660 | D55: 46094 | E55: =TEXT(C55:C19156,"yyyy-mmmm") -> 2025-January | F55: =IF(ISBLANK(D55), "Yes", IF((MONTH(D55)>MONTH(C55)),"Yes","No")) -> Yes | G55: =IF(ISBLANK(D55), DATEDIF(C55, MAX(D:D), "m"), DATEDIF(C55,D55, "m")) -> 14
...

Sheet Analysis
A1: Count of Months Renewed | B1: Cancellations | G1: Cohorts | H1: 1 | I1: 2 | J1: 3 | K1: Rounded Down | M1: Row Labels | N1: Initital Subscribers | O1: Remaining Subscribers
A2: Month Since Signup | B2: 2025-November | D2: Row Labels | E2: Count of Signup | G2: 2025-January | H2: =COUNTIFS(streaming_subscriptions!$E:$E, $G2, streaming_subscriptions!$G:$G, ">="&H$1) / COUNTIF(streaming_subscriptions!$E:$E, $G2) -> 0.54470199 | I2: =COUNTIFS(streaming_subscriptions!$E:$E, $G2, streaming_subscriptions!$G:$G, ">="&I$1) / COUNTIF(streaming_subscriptions!$E:$E, $G2) -> 0.39072848 | J2: =COUNTIFS(streaming_subscriptions!$E:$E, $G2, streaming_subscriptions!$G:$G, ">="&J$1) / COUNTIF(streaming_subscriptions!$E:$E, $G2) -> 0.30794702 | K2: =ROUNDDOWN(J2*100, 0)&"%" -> 30% | M2: 2025-January | N2: 604 | O2: =J2*E3 -> 186
A3: 0 | B3: 488 | D3: 2025-January | E3: 604 | G3: 2025-February | H3: =COUNTIFS(streaming_subscriptions!$E:$E, $G3, streaming_subscriptions!$G:$G, ">="&H$1) / COUNTIF(streaming_subscriptions!$E:$E, $G3) -> 0.53255426 | I3: =COUNTIFS(streaming_subscriptions!$E:$E, $G3, streaming_subscriptions!$G:$G, ">="&I$1) / COUNTIF(streaming_subscriptions!$E:$E, $G3) -> 0.37896494 | J3: =COUNTIFS(streaming_subscriptions!$E:$E, $G3, streaming_subscriptions!$G:$G, ">="&J$1) / COUNTIF(streaming_subscriptions!$E:$E, $G3) -> 0.278798 | K3: =ROUNDDOWN(J3*100, 0)&"%" -> 27% | M3: 2025-February | N3: 599 | O3: =J3*E4 -> 167
A4: 1 | B4: 174 | D4: 2025-February | E4: 599 | G4: 2025-March | H4: =COUNTIFS(streaming_subscriptions!$E:$E, $G4, streaming_subscriptions!$G:$G, ">="&H$1) / COUNTIF(streaming_subscriptions!$E:$E, $G4) -> 0.53012048 | I4: =COUNTIFS(streaming_subscriptions!$E:$E, $G4, streaming_subscriptions!$G:$G, ">="&I$1) / COUNTIF(streaming_subscriptions!$E:$E, $G4) -> 0.39307229 | J4: =COUNTIFS(streaming_subscriptions!$E:$E, $G4, streaming_subscriptions!$G:$G, ">="&J$1) / COUNTIF(streaming_subscriptions!$E:$E, $G4) -> 0.32078313 | K4: =ROUNDDOWN(J4*100, 0)&"%" -> 32% | M4: 2025-March | N4: 664 | O4: =J4*E5 -> 213
A5: 2 | B5: 85 | D5: 2025-March | E5: 664 | G5: 2025-April | H5: =COUNTIFS(streaming_subscriptions!$E:$E, $G5, streaming_subscriptions!$G:$G, ">="&H$1) / COUNTIF(streaming_subscriptions!$E:$E, $G5) -> 0.54610951 | I5: =COUNTIFS(streaming_subscriptions!$E:$E, $G5, streaming_subscriptions!$G:$G, ">="&I$1) / COUNTIF(streaming_subscriptions!$E:$E, $G5) -> 0.38184438 | J5: =COUNTIFS(streaming_subscriptions!$E:$E, $G5, streaming_subscriptions!$G:$G, ">="&J$1) / COUNTIF(streaming_subscriptions!$E:$E, $G5) -> 0.3054755 | K5: =ROUNDDOWN(J5*100, 0)&"%" -> 30% | M5: 2025-April | N5: 694 | O5: =J5*E6 -> 212
A6: 3 | B6: 72 | D6: 2025-April | E6: 694 | G6: 2025-May | H6: =COUNTIFS(streaming_subscriptions!$E:$E, $G6, streaming_subscriptions!$G:$G, ">="&H$1) / COUNTIF(streaming_subscriptions!$E:$E, $G6) -> 0.55582233 | I6: =COUNTIFS(streaming_subscriptions!$E:$E, $G6, streaming_subscriptions!$G:$G, ">="&I$1) / COUNTIF(streaming_subscriptions!$E:$E, $G6) -> 0.40816327 | J6: =COUNTIFS(streaming_subscriptions!$E:$E, $G6, streaming_subscriptions!$G:$G, ">="&J$1) / COUNTIF(streaming_subscriptions!$E:$E, $G6) -> 0.31932773 | K6: =ROUNDDOWN(J6*100, 0)&"%" -> 31% | M6: 2025-May | N6: 833 | O6: =J6*E7 -> 266
A7: 4 | B7: 51 | D7: 2025-May | E7: 833 | G7: 2025-June | H7: =COUNTIFS(streaming_subscriptions!$E:$E, $G7, streaming_subscriptions!$G:$G, ">="&H$1) / COUNTIF(streaming_subscriptions!$E:$E, $G7) -> 0.5752754 | I7: =COUNTIFS(streaming_subscriptions!$E:$E, $G7, streaming_subscriptions!$G:$G, ">="&I$1) / COUNTIF(streaming_subscriptions!$E:$E, $G7) -> 0.41003672 | J7: =COUNTIFS(streaming_subscriptions!$E:$E, $G7, streaming_subscriptions!$G:$G, ">="&J$1) / COUNTIF(streaming_subscriptions!$E:$E, $G7) -> 0.31578947 | K7: =ROUNDDOWN(J7*100, 0)&"%" -> 31% | M7: 2025-June | N7: 817 | O7: =J7*E8 -> 258
A8: 5 | B8: 32 | D8: 2025-June | E8: 817 | G8: 2025-July | H8: =COUNTIFS(streaming_subscriptions!$E:$E, $G8, streaming_subscriptions!$G:$G, ">="&H$1) / COUNTIF(streaming_subscriptions!$E:$E, $G8) -> 0.53783469 | I8: =COUNTIFS(streaming_subscriptions!$E:$E, $G8, streaming_subscriptions!$G:$G, ">="&I$1) / COUNTIF(streaming_subscriptions!$E:$E, $G8) -> 0.38183935 | J8: =COUNTIFS(streaming_subscriptions!$E:$E, $G8, streaming_subscriptions!$G:$G, ">="&J$1) / COUNTIF(streaming_subscriptions!$E:$E, $G8) -> 0.29336438 | K8: =ROUNDDOWN(J8*100, 0)&"%" -> 29% | M8: 2025-July | N8: 859 | O8: =J8*E9 -> 252
A9: 6 | B9: 32 | D9: 2025-July | E9: 859 | G9: 2025-August | H9: =COUNTIFS(streaming_subscriptions!$E:$E, $G9, streaming_subscriptions!$G:$G, ">="&H$1) / COUNTIF(streaming_subscriptions!$E:$E, $G9) -> 0.56701031 | I9: =COUNTIFS(streaming_subscriptions!$E:$E, $G9, streaming_subscriptions!$G:$G, ">="&I$1) / COUNTIF(streaming_subscriptions!$E:$E, $G9) -> 0.40206186 | J9: =COUNTIFS(streaming_subscriptions!$E:$E, $G9, streaming_subscriptions!$G:$G, ">="&J$1) / COUNTIF(streaming_subscriptions!$E:$E, $G9) -> 0.31443299 | K9: =ROUNDDOWN(J9*100, 0)&"%" -> 31% | M9: 2025-August | N9: 970 | O9: =J9*E10 -> 305
A10: 7 | B10: 20 | D10: 2025-August | E10: 970 | G10: 2025-September | H10: =COUNTIFS(streaming_subscriptions!$E:$E, $G10, streaming_subscriptions!$G:$G, ">="&H$1) / COUNTIF(streaming_subscriptions!$E:$E, $G10) -> 0.54371002 | I10: =COUNTIFS(streaming_subscriptions!$E:$E, $G10, streaming_subscriptions!$G:$G, ">="&I$1) / COUNTIF(streaming_subscriptions!$E:$E, $G10) -> 0.39872068 | J10: =COUNTIFS(streaming_subscriptions!$E:$E, $G10, streaming_subscriptions!$G:$G, ">="&J$1) / COUNTIF(streaming_subscriptions!$E:$E, $G10) -> 0.31876333 | K10: =ROUNDDOWN(J10*100, 0)&"%" -> 31% | M10: 2025-September | N10: 938 | O10: =J10*E11 -> 299
A11: 8 | B11: 112 | D11: 2025-September | E11: 938 | G11: 2025-October | H11: =COUNTIFS(streaming_subscriptions!$E:$E, $G11, streaming_subscriptions!$G:$G, ">="&H$1) / COUNTIF(streaming_subscriptions!$E:$E, $G11) -> 0.57911065 | I11: =COUNTIFS(streaming_subscriptions!$E:$E, $G11, streaming_subscriptions!$G:$G, ">="&I$1) / COUNTIF(streaming_subscriptions!$E:$E, $G11) -> 0.40641158 | J11: =COUNTIFS(streaming_subscriptions!$E:$E, $G11, streaming_subscriptions!$G:$G, ">="&J$1) / COUNTIF(streaming_subscriptions!$E:$E, $G11) -> 0.31334023 | K11: =ROUNDDOWN(J11*100, 0)&"%" -> 31% | M11: 2025-October | N11: 967 | O11: =J11*E12 -> 303
A12: 9 | B12: 11 | D12: 2025-October | E12: 967 | G12: 2025-November | H12: =COUNTIFS(streaming_subscriptions!$E:$E, $G12, streaming_subscriptions!$G:$G, ">="&H$1) / COUNTIF(streaming_subscriptions!$E:$E, $G12) -> 0.54688951 | I12: =COUNTIFS(streaming_subscriptions!$E:$E, $G12, streaming_subscriptions!$G:$G, ">="&I$1) / COUNTIF(streaming_subscriptions!$E:$E, $G12) -> 0.38532962 | J12: =COUNTIFS(streaming_subscriptions!$E:$E, $G12, streaming_subscriptions!$G:$G, ">="&J$1) / COUNTIF(streaming_subscriptions!$E:$E, $G12) -> 0.30640669 | K12: =ROUNDDOWN(J12*100, 0)&"%" -> 30% | M12: 2025-November | N12: 1077 | O12: =J12*E13 -> 330
D13: 2025-November | E13: 1077 | G13: 2025-December | H13: =COUNTIFS(streaming_subscriptions!$E:$E, $G13, streaming_subscriptions!$G:$G, ">="&H$1) / COUNTIF(streaming_subscriptions!$E:$E, $G13) -> 0.54520295 | I13: =COUNTIFS(streaming_subscriptions!$E:$E, $G13, streaming_subscriptions!$G:$G, ">="&I$1) / COUNTIF(streaming_subscriptions!$E:$E, $G13) -> 0.39944649 | J13: =COUNTIFS(streaming_subscriptions!$E:$E, $G13, streaming_subscriptions!$G:$G, ">="&J$1) / COUNTIF(streaming_subscriptions!$E:$E, $G13) -> 0.31273063 | K13: =ROUNDDOWN(J13*100, 0)&"%" -> 31% | M13: 2025-December | N13: 1084 | O13: =J13*E14 -> 339
D14: 2025-December | E14: 1084 | G14: 2026-January | H14: =COUNTIFS(streaming_subscriptions!$E:$E, $G14, streaming_subscriptions!$G:$G, ">="&H$1) / COUNTIF(streaming_subscriptions!$E:$E, $G14) -> 0.56265356 | I14: =COUNTIFS(streaming_subscriptions!$E:$E, $G14, streaming_subscriptions!$G:$G, ">="&I$1) / COUNTIF(streaming_subscriptions!$E:$E, $G14) -> 0.42669943 | J14: =COUNTIFS(streaming_subscriptions!$E:$E, $G14, streaming_subscriptions!$G:$G, ">="&J$1) / COUNTIF(streaming_subscriptions!$E:$E, $G14) -> 0.33333333 | K14: =ROUNDDOWN(J14*100, 0)&"%" -> 33% | M14: 2026-January | N14: 1221 | O14: =J14*E15 -> 407
D15: 2026-January | E15: 1221 | G15: 2026-February | H15: =COUNTIFS(streaming_subscriptions!$E:$E, $G15, streaming_subscriptions!$G:$G, ">="&H$1) / COUNTIF(streaming_subscriptions!$E:$E, $G15) -> 0.59792028 | I15: =COUNTIFS(streaming_subscriptions!$E:$E, $G15, streaming_subscriptions!$G:$G, ">="&I$1) / COUNTIF(streaming_subscriptions!$E:$E, $G15) -> 0.42461005 | J15: =COUNTIFS(streaming_subscriptions!$E:$E, $G15, streaming_subscriptions!$G:$G, ">="&J$1) / COUNTIF(streaming_subscriptions!$E:$E, $G15) -> 0.34142114 | K15: =ROUNDDOWN(J15*100, 0)&"%" -> 34% | M15: 2026-February | N15: 1154 | O15: =J15*E16 -> 394
D16: 2026-February | E16: 1154 | G16: 2026-March | H16: =COUNTIFS(streaming_subscriptions!$E:$E, $G16, streaming_subscriptions!$G:$G, ">="&H$1) / COUNTIF(streaming_subscriptions!$E:$E, $G16) -> 0.5852649 | I16: =COUNTIFS(streaming_subscriptions!$E:$E, $G16, streaming_subscriptions!$G:$G, ">="&I$1) / COUNTIF(streaming_subscriptions!$E:$E, $G16) -> 0.42963576 | J16: =COUNTIFS(streaming_subscriptions!$E:$E, $G16, streaming_subscriptions!$G:$G, ">="&J$1) / COUNTIF(streaming_subscriptions!$E:$E, $G16) -> 0.34023179 | K16: =ROUNDDOWN(J16*100, 0)&"%" -> 34% | M16: 2026-March | N16: 1208 | O16: =J16*E17 -> 411
D17: 2026-March | E17: 1208 | G17: 2026-April | H17: =COUNTIFS(streaming_subscriptions!$E:$E, $G17, streaming_subscriptions!$G:$G, ">="&H$1) / COUNTIF(streaming_subscriptions!$E:$E, $G17) -> 0.59557014 | I17: =COUNTIFS(streaming_subscriptions!$E:$E, $G17, streaming_subscriptions!$G:$G, ">="&I$1) / COUNTIF(streaming_subscriptions!$E:$E, $G17) -> 0.42575882 | J17: =COUNTIFS(streaming_subscriptions!$E:$E, $G17, streaming_subscriptions!$G:$G, ">="&J$1) / COUNTIF(streaming_subscriptions!$E:$E, $G17) -> 0.33552092 | K17: =ROUNDDOWN(J17*100, 0)&"%" -> 33% | M17: 2026-April | N17: 1219 | O17: =J17*E18 -> 409
D18: 2026-April | E18: 1219 | G18: 2026-May | H18: =COUNTIFS(streaming_subscriptions!$E:$E, $G18, streaming_subscriptions!$G:$G, ">="&H$1) / COUNTIF(streaming_subscriptions!$E:$E, $G18) -> 0.54702784 | I18: =COUNTIFS(streaming_subscriptions!$E:$E, $G18, streaming_subscriptions!$G:$G, ">="&I$1) / COUNTIF(streaming_subscriptions!$E:$E, $G18) -> 0.38299473 | J18: =COUNTIFS(streaming_subscriptions!$E:$E, $G18, streaming_subscriptions!$G:$G, ">="&J$1) / COUNTIF(streaming_subscriptions!$E:$E, $G18) -> 0.021820918 | K18: =ROUNDDOWN(J18*100, 0)&"%" -> 2% | M18: 2026-May | N18: 1329 | O18: =J18*E19 -> 29
D19: 2026-May | E19: 1329 | G19: 2026-June | H19: =COUNTIFS(streaming_subscriptions!$E:$E, $G19, streaming_subscriptions!$G:$G, ">="&H$1) / COUNTIF(streaming_subscriptions!$E:$E, $G19) -> 0.58640227 | I19: =COUNTIFS(streaming_subscriptions!$E:$E, $G19, streaming_subscriptions!$G:$G, ">="&I$1) / COUNTIF(streaming_subscriptions!$E:$E, $G19) -> 0.033994334 | J19: =COUNTIFS(streaming_subscriptions!$E:$E, $G19, streaming_subscriptions!$G:$G, ">="&J$1) / COUNTIF(streaming_subscriptions!$E:$E, $G19) -> 0 | K19: =ROUNDDOWN(J19*100, 0)&"%" -> 0% | M19: 2026-June | N19: 1412 | O19: =J19*E20 -> 0
D20: 2026-June | E20: 1412 | G20: 2026-July | H20: =COUNTIFS(streaming_subscriptions!$E:$E, $G20, streaming_subscriptions!$G:$G, ">="&H$1) / COUNTIF(streaming_subscriptions!$E:$E, $G20) -> 0.045423262 | I20: =COUNTIFS(streaming_subscriptions!$E:$E, $G20, streaming_subscriptions!$G:$G, ">="&I$1) / COUNTIF(streaming_subscriptions!$E:$E, $G20) -> 0 | J20: =COUNTIFS(streaming_subscriptions!$E:$E, $G20, streaming_subscriptions!$G:$G, ">="&J$1) / COUNTIF(streaming_subscriptions!$E:$E, $G20) -> 0 | K20: =ROUNDDOWN(J20*100, 0)&"%" -> 0% | M20: 2026-July | N20: 1453 | O20: =J20*E21 -> 0
D21: 2026-July | E21: 1453
D22: Grand Total | E22: 19102
